Workbook
Name ABS: 'Data Item PDF'!$B$2
Name ABS: 'Data Item'!$B$2
Name ACCESSMODE: 'Data Item PDF'!$B$3
Name ACCESSMODE: 'Data Item'!$B$3
Name ACDS: 'Data Item PDF'!$B$4
Name ACDS: 'Data Item'!$B$4
Name ACKA: 'Data Item PDF'!$B$5
Name ACKA: 'Data Item'!$B$5
Name ACKC10: 'Data Item PDF'!$B$12
Name ACKC10: 'Data Item'!$B$12
Name ACKC13: 'Data Item PDF'!$B$13
Name ACKC13: 'Data Item'!$B$13
Name ACKC15: 'Data Item PDF'!$B$14
Name ACKC15: 'Data Item'!$B$14
Name ACKC3: 'Data Item PDF'!$B$7
Name ACKC3: 'Data Item'!$B$7
Name ACKC5: 'Data Item PDF'!$B$8
Name ACKC5: 'Data Item'!$B$8
Name ACKC6: 'Data Item PDF'!$B$9
Name ACKC6: 'Data Item'!$B$9
Name ACKC7: 'Data Item PDF'!$B$10
Name ACKC7: 'Data Item'!$B$10
Name ACKC7A: 'Data Item PDF'!$B$11
Name ACKC7A: 'Data Item'!$B$11
Name AGENT: 'Data Item PDF'!$B$15
Name AGENT: 'Data Item'!$B$15
Name ALCD: 'Data Item PDF'!$B$16
Name ALCD: 'Data Item'!$B$16
Name ALED: 'Data Item PDF'!$B$17
Name ALED: 'Data Item'!$B$17
Name ALID: 'Data Item PDF'!$B$18
Name ALID: 'Data Item'!$B$18
Name ALTX: 'Data Item PDF'!$B$19
Name ALTX: 'Data Item'!$B$19
Name ATTRDATA: 'Data Item PDF'!$B$20
Name ATTRDATA: 'Data Item'!$B$20
Name ATTRID: 'Data Item PDF'!$B$21
Name ATTRID: 'Data Item'!$B$21
Name ATTRRELN: 'Data Item PDF'!$B$22
Name ATTRRELN: 'Data Item'!$B$22
Name BCDS: 'Data Item PDF'!$B$23
Name BCDS: 'Data Item'!$B$23
Name BCEQU: 'Data Item PDF'!$B$24
Name BCEQU: 'Data Item'!$B$24
Name BINLT: 'Data Item PDF'!$B$25
Name BINLT: 'Data Item'!$B$25
Name BLKDEF: 'Data Item PDF'!$B$26
Name BLKDEF: 'Data Item'!$B$26
Name BPD: 'Data Item PDF'!$B$27
Name BPD: 'Data Item'!$B$27
Name BYTMAX: 'Data Item PDF'!$B$28
Name BYTMAX: 'Data Item'!$B$28
Name CAACK: 'Data Item PDF'!$B$29
Name CAACK: 'Data Item'!$B$29
Name CARRIERACTION: 'Data Item PDF'!$B$30
Name CARRIERACTION: 'Data Item'!$B$30
Name CARRIERID: 'Data Item PDF'!$B$31
Name CARRIERID: 'Data Item'!$B$31
Name CARRIERSPEC: 'Data Item PDF'!$B$32
Name CARRIERSPEC: 'Data Item'!$B$32

Sheet SV & EC
B1: 0 | C1: 1 | D1: 2 | E1: 3 | F1: 4 | G1: 5 | H1: 6 | I1: 7 | J1: 8 | K1: 9 | L1: 10 | N1: 11 | O1: 13
B2: ID | C2: SV | D2: EC | E2: S7F23 | F2: Function | G2: Type | H2: Unit | I2: Max. | J2: Min. | K2: default | L2: Description | M2: HT-9040S | N2: HT-704X | O2: HT9045 HT9046 | P2: HT-2036 | Q2: HT-2000M | R2: HT-3600A | S2: HT-3309 | T2: HT-3350 | U2: HT-160
B3: 3 | C3: V | F3: GemClock | G3: ASCII | L3: Equipment clock | M3: V | N3: V | O3: V | P3: V | Q3: V | S3: V | T3: V | U3: V
B4: 4 | C4: V | F4: GemControlState | G4: UINT_1 | L4: Equipment connection status: 1: OffLine; 2:OnLine Local; 3:OnLine Remote; | M4: V | N4: V | O4: V | P4: V | Q4: V | S4: V | T4: V | U4: V
B5: 5 | C5: V | F5: GemLinkState | G5: UINT_1 | L5: Current connection status 0:Disabled; 1:Enabled/Not Communicating; 2: Communicating; | M5: V | N5: V | O5: V | P5: V | Q5: V | S5: V | T5: V | U5: V
B6: 6 | C6: V | F6: SECSCommunicationMode | G6: INT_1 | L6: 0:HSMS Mode 1:SECS Mode (Set By AP) | M6: V | N6: V | O6: V | P6: V | Q6: V | S6: V | T6: V | U6: V
B7: 9 | C7: V | F7: PreviousGemControlState | G7: UINT_1 | L7: Pre-Equipment connection status: 1: OffLine; 2:OnLine Local; 3:OnLine Remote; | O7: V
B8: 10 | C8: V | F8: CPU Frequence | G8: INT_4 | L8: CPU operate MHZ | M8: V | N8: V | O8: V | P8: V | Q8: V | S8: V | T8: V | U8: V
B9: 11 | C9: V | F9: CPU Manufacturer | G9: ASCII | L9: CPU Manufacturer | M9: V | N9: V | O9: V | P9: V | Q9: V | S9: V | T9: V | U9: V
B10: 12 | C10: V | F10: CPU Type | G10: ASCII | L10: CPU Type | M10: V | N10: V | O10: V | P10: V | Q10: V | S10: V | T10: V | U10: V
B11: 13 | C11: V | F11: Total Space Of Disk C | G11: INT_4 | L11: Total Space Of Disk C | M11: V | N11: V | O11: V | P11: V | Q11: V | S11: V | T11: V | U11: V
B12: 14 | C12: V | F12: Total Space Of Disk D | G12: INT_4 | L12: Total Space Of Disk D | M12: V | N12: V | O12: V | P12: V | Q12: V | S12: V | T12: V | U12: V
B13: 15 | C13: V | F13: Total FreeSpace Of Disk C | G13: INT_4 | L13: Total FreeSpace Of Disk C | M13: V | N13: V | O13: V | P13: V | Q13: V | S13: V | T13: V | U13: V
B14: 16 | C14: V | F14: Total FreeSpace Of Disk D | G14: INT_4 | L14: Total FreeSpace Of Disk D | M14: V | N14: V | O14: V | P14: V | Q14: V | S14: V | T14: V | U14: V
B15: 17 | C15: V | F15: Memory Load Percent | G15: UINT_4 | L15: Memory Load Percent | M15: V | N15: V | O15: V | P15: V | Q15: V | S15: V | T15: V | U15: V
B16: 18 | C16: V | F16: Memory Total Physic | G16: UINT_4 | L16: Memory Total Physic | M16: V | N16: V | O16: V | P16: V | Q16: V | S16: V | T16: V | U16: V
B17: 19 | C17: V | F17: Memory Avail Physic | G17: UINT_4 | L17: Memory Avail Physic | M17: V | N17: V | O17: V | P17: V | Q17: V | S17: V | T17: V | U17: V
B18: 24 | C18: V | F18: GemMDLN | G18: ASCII | L18: Handler Model | M18: V | N18: V | O18: V | P18: V | Q18: V | S18: V | T18: V | U18: V
B19: 25 | C19: V | F19: GemSOFTREV | G19: ASCII | L19: Software revision | M19: V | N19: V | O19: V | P19: V | Q19: V | S19: V | T19: V | U19: V
... B21: 57 | C21: V | F21: GemSpoolStartTime | G21: ASCII | L21: Spool start time | M21: V | N21: V | O21: V | P21: V | Q21: V | S21: V | T21: V | U21: V
B22: 68 | C22: V | D22: V | F22: Time Format | G22: UINT_1 | I22: 3 | J22: 0 | K22: 0 | L22: Time Format | M22: V | N22: V | O22: V | P22: V | Q22: V | S22: V | T22: V | U22: V
B23: 70 | C23: V | F23: Receipe Struct | G23: UINT_1 | L23: It is used to define the format of current setup file. 0: a singla file.; 1: multi-file such as the group of BLD .OFF ; 2: the directory as the setup file; | M23: V | N23: V | O23: V | P23: V | Q23: V | S23: V | T23: V | U23: V
B24: 71 | C24: V | F24: Receipe Extend | G24: ASCII | L24: Receipe extend filename | M24: V | N24: V | O24: V | P24: V | Q24: V | S24: V | T24: V | U24: V
B25: 1000 | C25: V | F25: Machine Define | G25: ASCII | L25: Handler define | M25: V | N25: V | O25: V | P25: V | Q25: V | U25: V
B26: 1001 | C26: V | F26: Machine Model | G26: ASCII | L26: Handler model | M26: V | N26: V | O26: V | P26: V | Q26: V | U26: V
B27: 1002 | C27: V | F27: Machine ID | G27: ASCII | L27: Handler ID | M27: V | N27: V | O27: V | P27: V | Q27: V | U27: V
B28: 1003 | C28: V | F28: Software Version | G28: ASCII | L28: Software Version | M28: V | N28: V | O28: V | P28: V | Q28: V | U28: V
B29: 1004 | C29: V | F29: Software Release Date | G29: ASCII | L29: Software Release Date | O29: V | P29: V | Q29: V | U29: V
B30: 1005 | C30: V | F30: Factory | G30: ASCII | L30: Factory | O30: V
B31: 1006 | C31: V | D31: V | F31: Lot ID | G31: ASCII | L31: Lot ID | M31: V | N31: V | P31: V | Q31: V | U31: V
B32: 1007 | C32: V | D32: V | F32: Operator ID | G32: ASCII | L32: Operator ID | M32: V | N32: V | O32: V | P32: V | Q32: V | U32: V
B33: 1008 | C33: V | F33: Run Mode | G33: ASCII | L33: 0:Normal; 1:RT; 2:EQC | M33: V | N33: V | P33: V | Q33: V | U33: V
B34: 1009 | C34: V | F34: Lot Start Time | G34: ASCII | L34: Lot Start Time | M34: V | O34: V | U34: V
B35: 1010 | C35: V | F35: Machine Pre State | G35: ASCII | L35: Pre-handler status | M35: V | N35: V | O35: V
B36: 1011 | C36: V | F36: Machine State | G36: ASCII | L36: Handler status "LOCK" "EMG 1" "EMG 2" "EMG 3" "EMG 4" "Power Off" "Homing" "Auto Retest" "HP Check" "Cleaning" "OCR Insp" "Reseting" "Piggy Back" "QA Mode" "Onecycle Cleaning" "No Tray" "Running" "Heater Wait" "Cooling Wait" "PAUSE" (Device in handler, only detect Hot Plate、Shuttle、Index Sucker、In\Out Arm Sucker) "HALT" (except PAUSE) "Index Check" "RUN CHECK" "Defrosting" "ATC Self Test" | M36: V | N36: V | O36: V | P36: V | Q36: V | U36: V
B37: 1012 | C37: V | F37: Index Arm1 Torque | G37: ASCII | L37: Index Arm1 torque value | M37: V | N37: V | O37: V
B38: 1013 | C38: V | F38: Index Arm2 Torque | G38: ASCII | L38: Index Arm2 torque value | M38: V | N38: V | O38: V
B39: 1014 | C39: V | F39: Tower Light Red | G39: INT_4 | L39: Tower Light-Red; 0:Off; 1:Light On; 2:Blink | M39: V | N39: V | O39: V | P39: V | Q39: V | U39: V
B40: 1015 | C40: V | F40: Tower Light Yellow | G40: INT_4 | L40: Tower Light-Yellow; 0:Off; 1:Light On; 2:Blink | M40: V | N40: V | O40: V | P40: V | Q40: V | U40: V
B41: 1016 | C41: V | F41: Tower Light Green | G41: INT_4 | L41: Tower Light-Green; 0:Off; 1:Light On; 2:Blink | M41: V | N41: V | O41: V | P41: V | Q41: V | U41: V
...

Sheet SV & EC_PDF
A1: ='SV & EC'!B2 -> ID | B1: ='SV & EC'!F2 -> Function | C1: ='SV & EC'!G2 -> Type | D1: ='SV & EC'!I2 -> Max. | E1: ='SV & EC'!J2 -> Min. | F1: ='SV & EC'!H2 -> Unit | G1: ='SV & EC'!L2 -> Description | H1: SV | I1: EC
A2: =IF('SV & EC'!B3="","",'SV & EC'!B3) -> 3 | B2: =IF('SV & EC'!F3="","",'SV & EC'!F3) -> GemClock | C2: =IF('SV & EC'!G3="","",'SV & EC'!G3) -> ASCII | D2: =IF('SV & EC'!I3="","",'SV & EC'!I3) | E2: =IF('SV & EC'!J3="","",'SV & EC'!J3) | F2: =IF('SV & EC'!H3="","",'SV & EC'!H3) | G2: =IF('SV & EC'!L3="","",'SV & EC'!L3) -> Equipment clock | H2: =IF('SV & EC'!C3="","",'SV & EC'!C3) -> V | I2: =IF('SV & EC'!D3="","",'SV & EC'!D3)
A3: =IF('SV & EC'!B4="","",'SV & EC'!B4) -> 4 | B3: =IF('SV & EC'!F4="","",'SV & EC'!F4) -> GemControlState | C3: =IF('SV & EC'!G4="","",'SV & EC'!G4) -> UINT_1 | D3: =IF('SV & EC'!I4="","",'SV & EC'!I4) | E3: =IF('SV & EC'!J4="","",'SV & EC'!J4) | F3: =IF('SV & EC'!H4="","",'SV & EC'!H4) | G3: =IF('SV & EC'!L4="","",'SV & EC'!L4) -> Equipment connection status: 1: OffLine; 2:OnLine Local; 3:OnLine Remote; | H3: =IF('SV & EC'!C4="","",'SV & EC'!C4) -> V | I3: =IF('SV & EC'!D4="","",'SV & EC'!D4)
A4: =IF('SV & EC'!B5="","",'SV & EC'!B5) -> 5 | B4: =IF('SV & EC'!F5="","",'SV & EC'!F5) -> GemLinkState | C4: =IF('SV & EC'!G5="","",'SV & EC'!G5) -> UINT_1 | D4: =IF('SV & EC'!I5="","",'SV & EC'!I5) | E4: =IF('SV & EC'!J5="","",'SV & EC'!J5) | F4: =IF('SV & EC'!H5="","",'SV & EC'!H5) | G4: =IF('SV & EC'!L5="","",'SV & EC'!L5) -> Current connection status 0:Disabled; 1:Enabled/Not Communicating; 2: Communicating; | H4: =IF('SV & EC'!C5="","",'SV & EC'!C5) -> V | I4: =IF('SV & EC'!D5="","",'SV & EC'!D5)
A5: =IF('SV & EC'!B6="","",'SV & EC'!B6) -> 6 | B5: =IF('SV & EC'!F6="","",'SV & EC'!F6) -> SECSCommunicationMode | C5: =IF('SV & EC'!G6="","",'SV & EC'!G6) -> INT_1 | D5: =IF('SV & EC'!I6="","",'SV & EC'!I6) | E5: =IF('SV & EC'!J6="","",'SV & EC'!J6) | F5: =IF('SV & EC'!H6="","",'SV & EC'!H6) | G5: =IF('SV & EC'!L6="","",'SV & EC'!L6) -> 0:HSMS Mode 1:SECS Mode (Set By AP) | H5: =IF('SV & EC'!C6="","",'SV & EC'!C6) -> V | I5: =IF('SV & EC'!D6="","",'SV & EC'!D6)
A6: =IF('SV & EC'!B7="","",'SV & EC'!B7) -> 9 | B6: =IF('SV & EC'!F7="","",'SV & EC'!F7) -> PreviousGemControlState | C6: =IF('SV & EC'!G7="","",'SV & EC'!G7) -> UINT_1 | D6: =IF('SV & EC'!I7="","",'SV & EC'!I7) | E6: =IF('SV & EC'!J7="","",'SV & EC'!J7) | F6: =IF('SV & EC'!H7="","",'SV & EC'!H7) | G6: =IF('SV & EC'!L7="","",'SV & EC'!L7) -> Pre-Equipment connection status: 1: OffLine; 2:OnLine Local; 3:OnLine Remote; | H6: =IF('SV & EC'!C7="","",'SV & EC'!C7) -> V | I6: =IF('SV & EC'!D7="","",'SV & EC'!D7)
A7: =IF('SV & EC'!B8="","",'SV & EC'!B8) -> 10 | B7: =IF('SV & EC'!F8="","",'SV & EC'!F8) -> CPU Frequence | C7: =IF('SV & EC'!G8="","",'SV & EC'!G8) -> INT_4 | D7: =IF('SV & EC'!I8="","",'SV & EC'!I8) | E7: =IF('SV & EC'!J8="","",'SV & EC'!J8) | F7: =IF('SV & EC'!H8="","",'SV & EC'!H8) | G7: =IF('SV & EC'!L8="","",'SV & EC'!L8) -> CPU operate MHZ | H7: =IF('SV & EC'!C8="","",'SV & EC'!C8) -> V | I7: =IF('SV & EC'!D8="","",'SV & EC'!D8)
A8: =IF('SV & EC'!B9="","",'SV & EC'!B9) -> 11 | B8: =IF('SV & EC'!F9="","",'SV & EC'!F9) -> CPU Manufacturer | C8: =IF('SV & EC'!G9="","",'SV & EC'!G9) -> ASCII | D8: =IF('SV & EC'!I9="","",'SV & EC'!I9) | E8: =IF('SV & EC'!J9="","",'SV & EC'!J9) | F8: =IF('SV & EC'!H9="","",'SV & EC'!H9) | G8: =IF('SV & EC'!L9="","",'SV & EC'!L9) -> CPU Manufacturer | H8: =IF('SV & EC'!C9="","",'SV & EC'!C9) -> V | I8: =IF('SV & EC'!D9="","",'SV & EC'!D9)
A9: =IF('SV & EC'!B10="","",'SV & EC'!B10) -> 12 | B9: =IF('SV & EC'!F10="","",'SV & EC'!F10) -> CPU Type | C9: =IF('SV & EC'!G10="","",'SV & EC'!G10) -> ASCII | D9: =IF('SV & EC'!I10="","",'SV & EC'!I10) | E9: =IF('SV & EC'!J10="","",'SV & EC'!J10) | F9: =IF('SV & EC'!H10="","",'SV & EC'!H10) | G9: =IF('SV & EC'!L10="","",'SV & EC'!L10) -> CPU Type | H9: =IF('SV & EC'!C10="","",'SV & EC'!C10) -> V | I9: =IF('SV & EC'!D10="","",'SV & EC'!D10)
A10: =IF('SV & EC'!B11="","",'SV & EC'!B11) -> 13 | B10: =IF('SV & EC'!F11="","",'SV & EC'!F11) -> Total Space Of Disk C | C10: =IF('SV & EC'!G11="","",'SV & EC'!G11) -> INT_4 | D10: =IF('SV & EC'!I11="","",'SV & EC'!I11) | E10: =IF('SV & EC'!J11="","",'SV & EC'!J11) | F10: =IF('SV & EC'!H11="","",'SV & EC'!H11) | G10: =IF('SV & EC'!L11="","",'SV & EC'!L11) -> Total Space Of Disk C | H10: =IF('SV & EC'!C11="","",'SV & EC'!C11) -> V | I10: =IF('SV & EC'!D11="","",'SV & EC'!D11)
A11: =IF('SV & EC'!B12="","",'SV & EC'!B12) -> 14 | B11: =IF('SV & EC'!F12="","",'SV & EC'!F12) -> Total Space Of Disk D | C11: =IF('SV & EC'!G12="","",'SV & EC'!G12) -> INT_4 | D11: =IF('SV & EC'!I12="","",'SV & EC'!I12) | E11: =IF('SV & EC'!J12="","",'SV & EC'!J12) | F11: =IF('SV & EC'!H12="","",'SV & EC'!H12) | G11: =IF('SV & EC'!L12="","",'SV & EC'!L12) -> Total Space Of Disk D | H11: =IF('SV & EC'!C12="","",'SV & EC'!C12) -> V | I11: =IF('SV & EC'!D12="","",'SV & EC'!D12)
A12: =IF('SV & EC'!B13="","",'SV & EC'!B13) -> 15 | B12: =IF('SV & EC'!F13="","",'SV & EC'!F13) -> Total FreeSpace Of Disk C | C12: =IF('SV & EC'!G13="","",'SV & EC'!G13) -> INT_4 | D12: =IF('SV & EC'!I13="","",'SV & EC'!I13) | E12: =IF('SV & EC'!J13="","",'SV & EC'!J13) | F12: =IF('SV & EC'!H13="","",'SV & EC'!H13) | G12: =IF('SV & EC'!L13="","",'SV & EC'!L13) -> Total FreeSpace Of Disk C | H12: =IF('SV & EC'!C13="","",'SV & EC'!C13) -> V | I12: =IF('SV & EC'!D13="","",'SV & EC'!D13)
A13: =IF('SV & EC'!B14="","",'SV & EC'!B14) -> 16 | B13: =IF('SV & EC'!F14="","",'SV & EC'!F14) -> Total FreeSpace Of Disk D | C13: =IF('SV & EC'!G14="","",'SV & EC'!G14) -> INT_4 | D13: =IF('SV & EC'!I14="","",'SV & EC'!I14) | E13: =IF('SV & EC'!J14="","",'SV & EC'!J14) | F13: =IF('SV & EC'!H14="","",'SV & EC'!H14) | G13: =IF('SV & EC'!L14="","",'SV & EC'!L14) -> Total FreeSpace Of Disk D | H13: =IF('SV & EC'!C14="","",'SV & EC'!C14) -> V | I13: =IF('SV & EC'!D14="","",'SV & EC'!D14)
... A249: =IF('SV & EC'!B250="","",'SV & EC'!B250) -> 1258 | B249: =IF('SV & EC'!F250="","",'SV & EC'!F250) -> SiteH Arm1 Yield | C249: =IF('SV & EC'!G250="","",'SV & EC'!G250) -> ASCII | D249: =IF('SV & EC'!I250="","",'SV & EC'!I250) | E249: =IF('SV & EC'!J250="","",'SV & EC'!J250) | F249: =IF('SV & EC'!H250="","",'SV & EC'!H250) -> Percentage | G249: =IF('SV & EC'!L250="","",'SV & EC'!L250) -> SiteH Arm1 Yield | H249: =IF('SV & EC'!C250="","",'SV & EC'!C250) -> V | I249: =IF('SV & EC'!D250="","",'SV & EC'!D250)
A250: =IF('SV & EC'!B254="","",'SV & EC'!B254) -> 1301 | B250: =IF('SV & EC'!F254="","",'SV & EC'!F254) -> SiteA Arm2 Yield | C250: =IF('SV & EC'!G254="","",'SV & EC'!G254) -> ASCII | D250: =IF('SV & EC'!I254="","",'SV & EC'!I254) | E250: =IF('SV & EC'!J254="","",'SV & EC'!J254) | F250: =IF('SV & EC'!H254="","",'SV & EC'!H254) -> Percentage | G250: =IF('SV & EC'!L254="","",'SV & EC'!L254) -> SiteA Arm2 Yield | H250: =IF('SV & EC'!C254="","",'SV & EC'!C254) -> V | I250: =IF('SV & EC'!D254="","",'SV & EC'!D254)
A251: =IF('SV & EC'!B255="","",'SV & EC'!B255) -> 1302 | B251: =IF('SV & EC'!F255="","",'SV & EC'!F255) -> SiteB Arm2 Yield | C251: =IF('SV & EC'!G255="","",'SV & EC'!G255) -> ASCII | D251: =IF('SV & EC'!I255="","",'SV & EC'!I255) | E251: =IF('SV & EC'!J255="","",'SV & EC'!J255) | F251: =IF('SV & EC'!H255="","",'SV & EC'!H255) -> Percentage | G251: =IF('SV & EC'!L255="","",'SV & EC'!L255) -> SiteB Arm2 Yield | H251: =IF('SV & EC'!C255="","",'SV & EC'!C255) -> V | I251: =IF('SV & EC'!D255="","",'SV & EC'!D255)
A252: =IF('SV & EC'!B256="","",'SV & EC'!B256) -> 1303 | B252: =IF('SV & EC'!F256="","",'SV & EC'!F256) -> SiteC Arm2 Yield | C252: =IF('SV & EC'!G256="","",'SV & EC'!G256) -> ASCII | D252: =IF('SV & EC'!I256="","",'SV & EC'!I256) | E252: =IF('SV & EC'!J256="","",'SV & EC'!J256) | F252: =IF('SV & EC'!H256="","",'SV & EC'!H256) -> Percentage | G252: =IF('SV & EC'!L256="","",'SV & EC'!L256) -> SiteC Arm2 Yield | H252: =IF('SV & EC'!C256="","",'SV & EC'!C256) -> V | I252: =IF('SV & EC'!D256="","",'SV & EC'!D256)
A253: =IF('SV & EC'!B257="","",'SV & EC'!B257) -> 1304 | B253: =IF('SV & EC'!F257="","",'SV & EC'!F257) -> SiteD Arm2 Yield | C253: =IF('SV & EC'!G257="","",'SV & EC'!G257) -> ASCII | D253: =IF('SV & EC'!I257="","",'SV & EC'!I257) | E253: =IF('SV & EC'!J257="","",'SV & EC'!J257) | F253: =IF('SV & EC'!H257="","",'SV & EC'!H257) -> Percentage | G253: =IF('SV & EC'!L257="","",'SV & EC'!L257) -> SiteD Arm2 Yield | H253: =IF('SV & EC'!C257="","",'SV & EC'!C257) -> V | I253: =IF('SV & EC'!D257="","",'SV & EC'!D257)
A254: =IF('SV & EC'!B258="","",'SV & EC'!B258) -> 1305 | B254: =IF('SV & EC'!F258="","",'SV & EC'!F258) -> SiteE Arm2 Yield | C254: =IF('SV & EC'!G258="","",'SV & EC'!G258) -> ASCII | D254: =IF('SV & EC'!I258="","",'SV & EC'!I258) | E254: =IF('SV & EC'!J258="","",'SV & EC'!J258) | F254: =IF('SV & EC'!H258="","",'SV & EC'!H258) -> Percentage | G254: =IF('SV & EC'!L258="","",'SV & EC'!L258) -> SiteE Arm2 Yield | H254: =IF('SV & EC'!C258="","",'SV & EC'!C258) -> V | I254: =IF('SV & EC'!D258="","",'SV & EC'!D258)
A255: =IF('SV & EC'!B259="","",'SV & EC'!B259) -> 1306 | B255: =IF('SV & EC'!F259="","",'SV & EC'!F259) -> SiteF Arm2 Yield | C255: =IF('SV & EC'!G259="","",'SV & EC'!G259) -> ASCII | D255: =IF('SV & EC'!I259="","",'SV & EC'!I259) | E255: =IF('SV & EC'!J259="","",'SV & EC'!J259) | F255: =IF('SV & EC'!H259="","",'SV & EC'!H259) -> Percentage | G255: =IF('SV & EC'!L259="","",'SV & EC'!L259) -> SiteF Arm2 Yield | H255: =IF('SV & EC'!C259="","",'SV & EC'!C259) -> V | I255: =IF('SV & EC'!D259="","",'SV & EC'!D259)
A256: =IF('SV & EC'!B260="","",'SV & EC'!B260) -> 1307 | B256: =IF('SV & EC'!F260="","",'SV & EC'!F260) -> SiteG Arm2 Yield | C256: =IF('SV & EC'!G260="","",'SV & EC'!G260) -> ASCII | D256: =IF('SV & EC'!I260="","",'SV & EC'!I260) | E256: =IF('SV & EC'!J260="","",'SV & EC'!J260) | F256: =IF('SV & EC'!H260="","",'SV & EC'!H260) -> Percentage | G256: =IF('SV & EC'!L260="","",'SV & EC'!L260) -> SiteG Arm2 Yield | H256: =IF('SV & EC'!C260="","",'SV & EC'!C260) -> V | I256: =IF('SV & EC'!D260="","",'SV & EC'!D260)
A257: =IF('SV & EC'!B261="","",'SV & EC'!B261) -> 1308 | B257: =IF('SV & EC'!F261="","",'SV & EC'!F261) -> SiteH Arm2 Yield | C257: =IF('SV & EC'!G261="","",'SV & EC'!G261) -> ASCII | D257: =IF('SV & EC'!I261="","",'SV & EC'!I261) | E257: =IF('SV & EC'!J261="","",'SV & EC'!J261) | F257: =IF('SV & EC'!H261="","",'SV & EC'!H261) -> Percentage | G257: =IF('SV & EC'!L261="","",'SV & EC'!L261) -> SiteH Arm2 Yield | H257: =IF('SV & EC'!C261="","",'SV & EC'!C261) -> V | I257: =IF('SV & EC'!D261="","",'SV & EC'!D261)
A258: =IF('SV & EC'!B262="","",'SV & EC'!B262) -> 1351 | B258: =IF('SV & EC'!F262="","",'SV & EC'!F262) -> ATC Arm1 Head 1 | C258: =IF('SV & EC'!G262="","",'SV & EC'!G262) -> ASCII | D258: =IF('SV & EC'!I262="","",'SV & EC'!I262) | E258: =IF('SV & EC'!J262="","",'SV & EC'!J262) | F258: =IF('SV & EC'!H262="","",'SV & EC'!H262) | G258: =IF('SV & EC'!L262="","",'SV & EC'!L262) -> ATC Arm1 Head 1 | H258: =IF('SV & EC'!C262="","",'SV & EC'!C262) -> V | I258: =IF('SV & EC'!D262="","",'SV & EC'!D262)
A259: =IF('SV & EC'!B263="","",'SV & EC'!B263) -> 1352 | B259: =IF('SV & EC'!F263="","",'SV & EC'!F263) -> ATC Arm1 Head 2 | C259: =IF('SV & EC'!G263="","",'SV & EC'!G263) -> ASCII | D259: =IF('SV & EC'!I263="","",'SV & EC'!I263) | E259: =IF('SV & EC'!J263="","",'SV & EC'!J263) | F259: =IF('SV & EC'!H263="","",'SV & EC'!H263) | G259: =IF('SV & EC'!L263="","",'SV & EC'!L263) -> ATC Arm1 Head 2 | H259: =IF('SV & EC'!C263="","",'SV & EC'!C263) -> V | I259: =IF('SV & EC'!D263="","",'SV & EC'!D263)
A260: =IF('SV & EC'!B264="","",'SV & EC'!B264) -> 1353 | B260: =IF('SV & EC'!F264="","",'SV & EC'!F264) -> ATC Arm1 Head 3 | C260: =IF('SV & EC'!G264="","",'SV & EC'!G264) -> ASCII | D260: =IF('SV & EC'!I264="","",'SV & EC'!I264) | E260: =IF('SV & EC'!J264="","",'SV & EC'!J264) | F260: =IF('SV & EC'!H264="","",'SV & EC'!H264) | G260: =IF('SV & EC'!L264="","",'SV & EC'!L264) -> ATC Arm1 Head 3 | H260: =IF('SV & EC'!C264="","",'SV & EC'!C264) -> V | I260: =IF('SV & EC'!D264="","",'SV & EC'!D264)
A261: =IF('SV & EC'!B265="","",'SV & EC'!B265) -> 1354 | B261: =IF('SV & EC'!F265="","",'SV & EC'!F265) -> ATC Arm1 Head 4 | C261: =IF('SV & EC'!G265="","",'SV & EC'!G265) -> ASCII | D261: =IF('SV & EC'!I265="","",'SV & EC'!I265) | E261: =IF('SV & EC'!J265="","",'SV & EC'!J265) | F261: =IF('SV & EC'!H265="","",'SV & EC'!H265) | G261: =IF('SV & EC'!L265="","",'SV & EC'!L265) -> ATC Arm1 Head 4 | H261: =IF('SV & EC'!C265="","",'SV & EC'!C265) -> V | I261: =IF('SV & EC'!D265="","",'SV & EC'!D265)
... A721: =IF('SV & EC'!B725="","",'SV & EC'!B725) -> 3576 | B721: =IF('SV & EC'!F725="","",'SV & EC'!F725) -> Use initial start delay in socket - Delay time of SOT to EOT over time_RT | C721: =IF('SV & EC'!G725="","",'SV & EC'!G725) -> FT_8 | D721: =IF('SV & EC'!I725="","",'SV & EC'!I725) | E721: =IF('SV & EC'!J725="","",'SV & EC'!J725) | F721: =IF('SV & EC'!H725="","",'SV & EC'!H725) -> Second | G721: =IF('SV & EC'!L725="","",'SV & EC'!L725) -> Use initial start delay in socket - Delay time of SOT to EOT over time_RT | H721: =IF('SV & EC'!C725="","",'SV & EC'!C725) -> V | I721: =IF('SV & EC'!D725="","",'SV & EC'!D725) -> V
A722: =IF('SV & EC'!B726="","",'SV & EC'!B726) | B722: =IF('SV & EC'!F726="","",'SV & EC'!F726) | C722: =IF('SV & EC'!G726="","",'SV & EC'!G726) | F722: =IF('SV & EC'!H726="","",'SV & EC'!H726) | G722: =IF('SV & EC'!L726="","",'SV & EC'!L726) | H722: =IF('SV & EC'!C726="","",'SV & EC'!C726) | I722: =IF('SV & EC'!D726="","",'SV & EC'!D726)
A723: =IF('SV & EC'!B727="","",'SV & EC'!B727) | B723: =IF('SV & EC'!F727="","",'SV & EC'!F727) | C723: =IF('SV & EC'!G727="","",'SV & EC'!G727) | F723: =IF('SV & EC'!H727="","",'SV & EC'!H727) | G723: =IF('SV & EC'!L727="","",'SV & EC'!L727) | H723: =IF('SV & EC'!C727="","",'SV & EC'!C727) | I723: =IF('SV & EC'!D727="","",'SV & EC'!D727)
A724: =IF('SV & EC'!B728="","",'SV & EC'!B728) -> 3600 | B724: =IF('SV & EC'!F728="","",'SV & EC'!F728) -> Bin 0 Tray Select | C724: =IF('SV & EC'!G728="","",'SV & EC'!G728) -> INT_4 | D724: =IF('SV & EC'!I728="","",'SV & EC'!I728) -> 9 | E724: =IF('SV & EC'!J728="","",'SV & EC'!J728) -> 0 | F724: =IF('SV & EC'!H728="","",'SV & EC'!H728) | G724: =IF('SV & EC'!L728="","",'SV & EC'!L728) -> 0:Auto1; 1:Auto2; 2:Auto3; 3:Fix1; 4:Fix2; 5:Fix3; 6:Fix4; 7:Fix5; 8:Fix6 ;9: Not In Use | H724: =IF('SV & EC'!C728="","",'SV & EC'!C728) -> V | I724: =IF('SV & EC'!D728="","",'SV & EC'!D728) -> V
A725: =IF('SV & EC'!B729="","",'SV & EC'!B729) -> 3601 | B725: =IF('SV & EC'!F729="","",'SV & EC'!F729) -> Bin 1 Tray Select | C725: =IF('SV & EC'!G729="","",'SV & EC'!G729) -> INT_4 | D725: =IF('SV & EC'!I729="","",'SV & EC'!I729) -> 9 | E725: =IF('SV & EC'!J729="","",'SV & EC'!J729) -> 0 | F725: =IF('SV & EC'!H729="","",'SV & EC'!H729) | G725: =IF('SV & EC'!L729="","",'SV & EC'!L729) -> 0:Auto1; 1:Auto2; 2:Auto3; 3:Fix1; 4:Fix2; 5:Fix3; 6:Fix4; 7:Fix5; 8:Fix6 ;9: Not In Use | H725: =IF('SV & EC'!C729="","",'SV & EC'!C729) -> V | I725: =IF('SV & EC'!D729="","",'SV & EC'!D729) -> V
A726: =IF('SV & EC'!B730="","",'SV & EC'!B730) -> 3602 | B726: =IF('SV & EC'!F730="","",'SV & EC'!F730) -> Bin 2 Tray Select | C726: =IF('SV & EC'!G730="","",'SV & EC'!G730) -> INT_4 | D726: =IF('SV & EC'!I730="","",'SV & EC'!I730) -> 9 | E726: =IF('SV & EC'!J730="","",'SV & EC'!J730) -> 0 | F726: =IF('SV & EC'!H730="","",'SV & EC'!H730) | G726: =IF('SV & EC'!L730="","",'SV & EC'!L730) -> 0:Auto1; 1:Auto2; 2:Auto3; 3:Fix1; 4:Fix2; 5:Fix3; 6:Fix4; 7:Fix5; 8:Fix6 ;9: Not In Use | H726: =IF('SV & EC'!C730="","",'SV & EC'!C730) -> V | I726: =IF('SV & EC'!D730="","",'SV & EC'!D730) -> V
A727: =IF('SV & EC'!B731="","",'SV & EC'!B731) -> 3603 | B727: =IF('SV & EC'!F731="","",'SV & EC'!F731) -> Bin 3 Tray Select | C727: =IF('SV & EC'!G731="","",'SV & EC'!G731) -> INT_4 | D727: =IF('SV & EC'!I731="","",'SV & EC'!I731) -> 9 | E727: =IF('SV & EC'!J731="","",'SV & EC'!J731) -> 0 | F727: =IF('SV & EC'!H731="","",'SV & EC'!H731) | G727: =IF('SV & EC'!L731="","",'SV & EC'!L731) -> 0:Auto1; 1:Auto2; 2:Auto3; 3:Fix1; 4:Fix2; 5:Fix3; 6:Fix4; 7:Fix5; 8:Fix6 ;9: Not In Use | H727: =IF('SV & EC'!C731="","",'SV & EC'!C731) -> V | I727: =IF('SV & EC'!D731="","",'SV & EC'!D731) -> V
A728: =IF('SV & EC'!B732="","",'SV & EC'!B732) -> 3604 | B728: =IF('SV & EC'!F732="","",'SV & EC'!F732) -> Bin 4 Tray Select | C728: =IF('SV & EC'!G732="","",'SV & EC'!G732) -> INT_4 | D728: =IF('SV & EC'!I732="","",'SV & EC'!I732) -> 9 | E728: =IF('SV & EC'!J732="","",'SV & EC'!J732) -> 0 | F728: =IF('SV & EC'!H732="","",'SV & EC'!H732) | G728: =IF('SV & EC'!L732="","",'SV & EC'!L732) -> 0:Auto1; 1:Auto2; 2:Auto3; 3:Fix1; 4:Fix2; 5:Fix3; 6:Fix4; 7:Fix5; 8:Fix6 ;9: Not In Use | H728: =IF('SV & EC'!C732="","",'SV & EC'!C732) -> V | I728: =IF('SV & EC'!D732="","",'SV & EC'!D732) -> V
A729: =IF('SV & EC'!B733="","",'SV & EC'!B733) -> 3605 | B729: =IF('SV & EC'!F733="","",'SV & EC'!F733) -> Bin 5 Tray Select | C729: =IF('SV & EC'!G733="","",'SV & EC'!G733) -> INT_4 | D729: =IF('SV & EC'!I733="","",'SV & EC'!I733) -> 9 | E729: =IF('SV & EC'!J733="","",'SV & EC'!J733) -> 0 | F729: =IF('SV & EC'!H733="","",'SV & EC'!H733) | G729: =IF('SV & EC'!L733="","",'SV & EC'!L733) -> 0:Auto1; 1:Auto2; 2:Auto3; 3:Fix1; 4:Fix2; 5:Fix3; 6:Fix4; 7:Fix5; 8:Fix6 ;9: Not In Use | H729: =IF('SV & EC'!C733="","",'SV & EC'!C733) -> V | I729: =IF('SV & EC'!D733="","",'SV & EC'!D733) -> V
A730: =IF('SV & EC'!B734="","",'SV & EC'!B734) -> 3606 | B730: =IF('SV & EC'!F734="","",'SV & EC'!F734) -> Bin 6 Tray Select | C730: =IF('SV & EC'!G734="","",'SV & EC'!G734) -> INT_4 | D730: =IF('SV & EC'!I734="","",'SV & EC'!I734) -> 9 | E730: =IF('SV & EC'!J734="","",'SV & EC'!J734) -> 0 | F730: =IF('SV & EC'!H734="","",'SV & EC'!H734) | G730: =IF('SV & EC'!L734="","",'SV & EC'!L734) -> 0:Auto1; 1:Auto2; 2:Auto3; 3:Fix1; 4:Fix2; 5:Fix3; 6:Fix4; 7:Fix5; 8:Fix6 ;9: Not In Use | H730: =IF('SV & EC'!C734="","",'SV & EC'!C734) -> V | I730: =IF('SV & EC'!D734="","",'SV & EC'!D734) -> V
A731: =IF('SV & EC'!B735="","",'SV & EC'!B735) -> 3607 | B731: =IF('SV & EC'!F735="","",'SV & EC'!F735) -> Bin 7 Tray Select | C731: =IF('SV & EC'!G735="","",'SV & EC'!G735) -> INT_4 | D731: =IF('SV & EC'!I735="","",'SV & EC'!I735) -> 9 | E731: =IF('SV & EC'!J735="","",'SV & EC'!J735) -> 0 | F731: =IF('SV & EC'!H735="","",'SV & EC'!H735) | G731: =IF('SV & EC'!L735="","",'SV & EC'!L735) -> 0:Auto1; 1:Auto2; 2:Auto3; 3:Fix1; 4:Fix2; 5:Fix3; 6:Fix4; 7:Fix5; 8:Fix6 ;9: Not In Use | H731: =IF('SV & EC'!C735="","",'SV & EC'!C735) -> V | I731: =IF('SV & EC'!D735="","",'SV & EC'!D735) -> V
A732: =IF('SV & EC'!B736="","",'SV & EC'!B736) -> 3608 | B732: =IF('SV & EC'!F736="","",'SV & EC'!F736) -> Bin 8 Tray Select | C732: =IF('SV & EC'!G736="","",'SV & EC'!G736) -> INT_4 | D732: =IF('SV & EC'!I736="","",'SV & EC'!I736) -> 9 | E732: =IF('SV & EC'!J736="","",'SV & EC'!J736) -> 0 | F732: =IF('SV & EC'!H736="","",'SV & EC'!H736) | G732: =IF('SV & EC'!L736="","",'SV & EC'!L736) -> 0:Auto1; 1:Auto2; 2:Auto3; 3:Fix1; 4:Fix2; 5:Fix3; 6:Fix4; 7:Fix5; 8:Fix6 ;9: Not In Use | H732: =IF('SV & EC'!C736="","",'SV & EC'!C736) -> V | I732: =IF('SV & EC'!D736="","",'SV & EC'!D736) -> V
A733: =IF('SV & EC'!B737="","",'SV & EC'!B737) -> 3609 | B733: =IF('SV & EC'!F737="","",'SV & EC'!F737) -> Bin 9 Tray Select | C733: =IF('SV & EC'!G737="","",'SV & EC'!G737) -> INT_4 | D733: =IF('SV & EC'!I737="","",'SV & EC'!I737) -> 9 | E733: =IF('SV & EC'!J737="","",'SV & EC'!J737) -> 0 | F733: =IF('SV & EC'!H737="","",'SV & EC'!H737) | G733: =IF('SV & EC'!L737="","",'SV & EC'!L737) -> 0:Auto1; 1:Auto2; 2:Auto3; 3:Fix1; 4:Fix2; 5:Fix3; 6:Fix4; 7:Fix5; 8:Fix6 ;9: Not In Use | H733: =IF('SV & EC'!C737="","",'SV & EC'!C737) -> V | I733: =IF('SV & EC'!D737="","",'SV & EC'!D737) -> V
A734: =IF('SV & EC'!B738="","",'SV & EC'!B738) -> 3610 | B734: =IF('SV & EC'!F738="","",'SV & EC'!F738) -> Bin 10 Tray Select | C734: =IF('SV & EC'!G738="","",'SV & EC'!G738) -> INT_4 | D734: =IF('SV & EC'!I738="","",'SV & EC'!I738) -> 9 | E734: =IF('SV & EC'!J738="","",'SV & EC'!J738) -> 0 | F734: =IF('SV & EC'!H738="","",'SV & EC'!H738) | G734: =IF('SV & EC'!L738="","",'SV & EC'!L738) -> 0:Auto1; 1:Auto2; 2:Auto3; 3:Fix1; 4:Fix2; 5:Fix3; 6:Fix4; 7:Fix5; 8:Fix6 ;9: Not In Use | H734: =IF('SV & EC'!C738="","",'SV & EC'!C738) -> V | I734: =IF('SV & EC'!D738="","",'SV & EC'!D738) -> V
...

Sheet CEID Report
B2: CEID | C2: Report ID | D2: SV ID | E2: Remark | F2: HT9040S | G2: HT-704X | H2: HT9045 HT9046 | I2: HT-2036 | J2: HT-2000M
B3: 1 | C3: 1 | D3: 1027 | E3: Press Start button without IC inside handler | F3: V | G3: V | H3: V | I3: V | J3: V
B4: 2 | C4: 2 | D4: 1027 | E4: Press Pause button | F4: V | G4: V | H4: V | I4: V | J4: V
B5: 3 | C5: 3 | D5: 1027 | E5: Press One Cycle button | F5: V | G5: V | H5: V | I5: V | J5: V
B6: 4 | C6: 4 | D6: 1027 | E6: Press Clean Out button | F6: V | G6: V | H6: V | I6: V | J6: V
B7: 5 | C7: 5 | D7: 1027 | E7: Press Clear Count button | F7: V | G7: V | H7: V | I7: V | J7: V
B8: 6 | C8: 6 | D8: 1027 | E8: Press Lot Start button | F8: V | G8: V | H8: V
B9: 7 | C9: 7 | D9: 1027 | E9: Press Lot button | F9: V | G9: V | H9: V
B10: 8 | C10: 8 | D10: 1027 | E10: Press Lot End | F10: V | G10: V | H10: V
B11: 9 | C11: 9 | D11: 1027 | E11: Switching Real/Dummy Mode | F11: V | G11: V | H11: V | I11: V | J11: V
B12: 10 | C12: 10 | D12: 1027 | E12: Switching Tester Online/Offline Mode | F12: V | G12: V | H12: V | I12: V | J12: V
B13: 11 | C13: 11 | D13: 1027 | E13: Switching Production / Adjustment mode | F13: V | G13: V | H13: V
B14: 12 | C14: 12 | D14: 1027 | E14: Switching Normal/Engineering mode | F14: V | G14: V | H14: V
B15: 13 | C15: 13 | D15: 1027 | E15: Switching Ambient/Temperature | F15: V | G15: V | H15: V
B16: 14 | C16: 14 | D16: 1027 | E16: Switching Start Mode | F16: V | G16: V | H16: V | I16: V | J16: V
B17: 15 | C17: 15 | D17: 1027 | E17: Switching setup file | F17: V | G17: V | H17: V | I17: V | J17: V
B18: 16 | C18: 16 | D18: 1027 | E18: Switching User Level | F18: V | G18: V | H18: V | I18: V | J18: V
B19: 17 | C19: 17 | D19: 1027 | E19: Enter Tool Page | F19: V | G19: V | H19: V | I19: V | J19: V
B20: 18 | C20: 18 | D20: 1027 | E20: Enter Maintenance Page | F20: V | G20: V | H20: V | I20: V | J20: V
B21: 19 | C21: 19 | D21: 1027 | E21: Enter Offset Page | F21: V | G21: V | H21: V | I21: V | J21: V
B22: 20 | C22: 20 | D22: 1027 | E22: Enter Speed Page | F22: V | G22: V | H22: V | I22: V | J22: V
B23: 21 | C23: 21 | D23: 1027 | E23: Enter I/O Page | F23: V | G23: V | H23: V | I23: V | J23: V
B24: 22 | C24: 22 | D24: 1027 | E24: Enter Message Page | F24: V | G24: V | H24: V | I24: V | J24: V
B25: 23 | C25: 23 | D25: 1027 | E25: Enter Debug Page | F25: V | G25: V | H25: V | I25: V | J25: V
B26: 24 | C26: 24 | D26: 1027 | E26: Press Exit button | F26: V | G26: V | H26: V | I26: V | J26: V
B27: 25 | C27: 25 | D27: 1027 | E27: Press Home button | F27: V | G27: V | H27: V | I27: V | J27: V
B28: 26 | C28: 26 | D28: 1027 | E28: Get Test Result | F28: V | G28: V | H28: V | I28: V | J28: V
B29: 27 | C29: 27 | D29: 1027 | E29: Change Machine State | F29: V | G29: V | H29: V
B30: 28 | C30: 28 | D30: 1027 | E30: Press Retry button | F30: V | G30: V | H30: V | I30: V | J30: V
B31: 29 | C31: 29 | D31: 1027 | E31: Press Skip button | F31: V | G31: V | H31: V | I31: V | J31: V
B32: 30 | C32: 30 | D32: 1027 | E32: Press Alarm Reset button | F32: V | G32: V | H32: V | I32: V | J32: V
B33: 31 | C33: 31 | D33: 1027 | E33: Press Tray End button | F33: V | G33: V | H33: V
B34: 32 | C34: 32 | D34: 1027 | E34: Press Tray Feed button | F34: V | G34: V | H34: V
B35: 33 | C35: 33 | D35: 1027 | E35: Press Reset button | F35: V | G35: V | H35: V
B36: 34 | C36: 34 | D36: 1027 | E36: Auto Clean Start | F36: V | G36: V | H36: V
B37: 35 | C37: 35 | D37: 1027 | E37: Auto 1 Full | F37: V | G37: V | H37: V
B38: 36 | C38: 36 | D38: 1027 | E38: Auto 2 Full | F38: V | G38: V | H38: V
B39: 37 | C39: 37 | D39: 1027 | E39: Auto 3 Full | F39: V | G39: V | H39: V
B40: 38 | C40: 38 | D40: 1027 | E40: Fix 1 Full | F40: V | G40: V | H40: V
B41: 39 | C41: 39 | D41: 1027 | E41: Fix 2 Full | F41: V | G41: V | H41: V
...

Sheet Remote Command
B1: S2,F41 Host Command Send (HCS)
B2: Command | C2: Remark | D2: Valid Machine State | E2: HT9040S | F2: HT-704X | G2: HT9045 HT9046 | H2: HT-2036 | I2: HT-2000M
B3: PAUSE | C3: Handler is pause. | D3: Not including below status： "LOCK" "EMG 1" "EMG 2" "EMG 3" "EMG 4" "Power Off" | E3: V | F3: V | G3: V | H3: V | I3: V
B4: ONE_CYCLE | C4: Handler is executing One Cycle | D4: "Pause" | E4: V | F4: V | G4: V | H4: V | I4: V
B5: CLEAN_OUT | C5: Handler is executing Clean Out | D5: "Pause" | E5: V | F5: V | G5: V | H5: V | I5: V
B6: AUTO_CLEAN | C6: Handler is executing Auto Clean | D6: "Running" "HALT" "PAUSE" | E6: V | F6: V | G6: V
B7: SWITCH_TO_FT | C7: Switch to FT Mode. | D7: "HALT" | E7: V | F7: V | G7: V | H7: V | I7: V
B8: SWITCH_TO_RT | C8: Switch to RT Mode. | D8: "HALT" | E8: V | F8: V | G8: V | H8: V | I8: V
B9: START | C9: User press START button, and host sure the value is correct, then handler may start to run. Handler won't action when host send command directly, and START button doesn't be pressed. | D9: "RUN CHECK" | E9: V | G9: V | H9: V | I9: V
B10: HALT | C10: Use this command to stop handler, when user press START button, and host found the value is error. | D10: "RUN CHECK" | G10: V
B11: CONTINUE_RETEST_ART | C11: Switch to Retest ART mode. | D11: "HALT" "Pause" | G11: V
B12: CONTINUE_START_ART | C12: Switch to Continue ART mode. | D12: "HALT" "Pause" | G12: V
B13: DOWNLOAD_RECIPE_BY_FTP | C13: Download setup file from FTP. | D13: "HALT" | G13: V
B14: INITIAL_START_ART | C14: Switch to Initial ART mode. | D14: "HALT" | G14: V
B15: UPLOAD_RECIPE_BY_FTP | C15: Upload file to FTP | D15: "HALT" "Pause" | E15: V | F15: V
B16: PP_PASSWORD | C16: Change user's password. | E16: V | F16: V | G16: V | H16: V | I16: V
B17: PP_SELECT | C17: Switching setup file | D17: "HALT" | E17: V | F17: V
B18: PP_MUSIC | C18: Buzzer is on | E18: V | F18: V | G18: V | H18: V | I18: V
B19: PP_SIGNALTOWER | C19: Tower Light | E19: V | F19: V | G19: V | H19: V | I19: V
B20: ONLINE_LOCAL | C20: Switch to LOCAL MODE. | E20: V | F20: V | G20: V | H20: V | I20: V
B21: ONLINE_REMOTE | C21: Switch to REMOTE MODE. | E21: V | F21: V | G21: V | H21: V | I21: V
B22: REMOTE_UPDATE_PROGRAM | C22: update new program | E22: V | F22: V
B23: CLEAN_AUTO_SORT_COUNT | C23: Clean Auto Sort Count. | E23: V | F23: V
B24: RETEST_MRT | C24: Switch to Retest MRT mode. | D24: "HALT" "Pause" | F24: V
B25: CONTINUE_START_MRT | C25: Switch to Continue MRT mode. | D25: "HALT" "Pause" | F25: V
B26: INITIAL_START_MRT | C26: Switch to Initial MRT mode. | D26: "HALT" | F26: V
B27: HOME | C27: Machine Homing | F27: V
B28: STOP | C28: Handler Run Clean Out | F28: V
B29: RESUME | C29: Unlock SECS Control | F29: V
B30: NG_ART | C30: Check Run Auto Retest | F30: V
B31: EESUG_OFFSET | C31: Handler get Offset data | D31: "Running" "HALT" "PAUSE" | F31: V
B32: AUTO_RETEST | C32: Auto Retest | G32: V
B33: TRAY_FEED | C33: Tray Feed | G33: V
B34: CASSETTEDATA | C34: Cassette data | G34: V
B35: CASSETTE_OUT | C35: Cassette out List | G35: V
B36: CASSETTE_REJECT | C36: Cassette data error | G36: V
B37: CASSETTE_START | C37: Cassette List Start | G37: V
B38: LOTSTART | C38: Lot start | G38: V
B39: SET_PICKER_COUNT | C39: <CPNAME> is the SVID want to set <CPVAL> is the count which will set to SVID | D39: "HALT" | G39: V

Sheet AlarmReport
A1: Alarm Description for HT9045/HT9046 | E1: SECS Alarm Report Format | H1: Alarm Code for HT9045
A2: Alarm Class | B2: Jam | C2: 1 | E2: <L[7] <A[14] Alarm Time(20140526173030)> <U4[1] Alarm Cless(1)> <U4[1] Alarm Code(101000000)> <U4[1] Alarm Type(1)> <U4[1] Mess Type(0)> <A[41] Alarm Text([M01] Motor Error --Motor Power Off Error)> <A[6] Alarm Des(MTrayZ)> > | H2: X | I2: XX | J2: XXXXXX
B3: Event | C3: 2 | H3: Class | I3: Position | J3: Jam Code
B4: Message | C4: 3
A5: Alarm Code | B5: XXXXXXXXX | C5: There are a total of 9 characters.
A6: Alarm Text | B6: Wrong Message | C6: Alarm message
A7: Alarm Des | B7: Position Alarm | C7: Alarm position
A8: Alarm Sub Message | B8: The first code is for JAM RATE using (0, or 1), the other are sub-message. CSV format.
E13: JAM0101 | F13: In Arm Pickup error from Loader | G13: A, B, C
E14: JAM0101 | F14: In Arm Pickup error from Loader | G14: A, B
E15: JAM0101 | F15: In Arm Pickup error from Loader (Again) | G15: A, B
E16: Mes0101 | F16: In Arm Pickup error from Loader (Again) | G16: A
A18: Alarm Description for HT7045 | H18: Alarm Code for HT7045
A19: Alarm Class | B19: Jam | C19: 1 | H19: X | I19: XX | J19: XXXXXX
B20: Event | C20: 2 | H20: Class | I20: Type | J20: Jam Code
B21: Message | C21: 3
A22: Alarm Code | B22: XXXXXXXXX | C22: There are a total of 9 characters.
A23: Alarm Type | B23: Jam | C23: 1-13
B24: Event | C24: 1
B25: Message | C25: 1-5
A26: Mess Type | B26: Jam | C26: 0
B27: Error | C27: 1
B28: Message | C28: 2
A29: Alarm Text | B29: Wrong Message | C29: Alarm message
A30: Alarm Des | B30: Position Alarm | C30: Alarm position
A33: Alarm Description for HT2036、HT2000M
A34: Alarm Class | B34: Jam | C34: 1
A35: Alarm Code | B35: XXXXX | C35: There are a total of 5 characters.
A36: Mess Type | B36: Jam | C36: 0,4,5,6,9
A37: Alarm Text | B37: Wrong Message | C37: Alarm message
A38: Alarm Des | B38: Position Alarm | C38: Alarm position

Sheet AlarmCodeList_HT9045
A1: Type | B1: Position | C1: ALID | D1: ALTX | H1: No. | I1: Position
A2: 0 | B2: Event | C2: 0 | D2: Unknown alarm code | H2: 0 | I2: Event
A3: 3 | B3: Input Arm | C3: 301000101 | D3: Device pick-up error on the tray | H3: 1 | I3: Input Arm
A4: 1 | B4: Input Arm | C4: 101000109 | D4: Device pick-up error on Hot Plate | H4: 2 | I4: Output Arm
A5: 1 | B5: Input Arm | C5: 101000110 | D5: Device pick-up error on Clean Kit | H5: 3 | I5: Index Unit
A6: 1 | B6: Input Arm | C6: 101000111 | D6: Device pick-up error on Shuttle | H6: 4 | I6: Input Shuttle
A7: 1 | B7: Input Arm | C7: 101000112 | D7: Device pick up error on input rotate kit! | H7: 5 | I7: Output Shuttle
A8: 1 | B8: Input Arm | C8: 101000114 | D8: Close site pick-up IC error, take out ic. | H8: 6 | I8: Empty Tray Arm
A9: 1 | B9: Input Arm | C9: 101000115 | D9: Clean pad pick-up error on shuttle | H9: 7 | I9: Tester I/F
A10: 2 | B10: Input Arm | C10: 201000119 | D10: Loading count is less than ART setting count | H10: 8 | I10: Scanner
A11: 2 | B11: Input Arm | C11: 201000120 | D11: Loading count is more than ART setting count | H11: 9 | I11: Tray Loader
A12: 1 | B12: Input Arm | C12: 101000126 | D12: In arm Device drop error | H12: 10 | I12: Empty Tray
A13: 1 | B13: Input Arm | C13: 101000127 | D13: In arm Vacuum sensor OFF error | H13: 11 | I13: Tray Unloader 1
... A25: 1 | B25: Input Arm | C25: 101000160 | D25: Hot Plate 1 device height error by Laser!! | H25: 23 | I25: Message
A26: 1 | B26: Input Arm | C26: 101000161 | D26: Hot Plate 2 device height error by Laser!!
A27: 1 | B27: Input Arm | C27: 101000162 | D27: Hot Plate 1 device lose error by Laser!!
A28: 1 | B28: Input Arm | C28: 101000163 | D28: Hot Plate 2 device lose error by Laser!!
A29: 2 | B29: Input Arm | C29: 201000164 | D29: Input arm laser read error, please check COM port connection!!
A30: 2 | B30: Input Arm | C30: 201000165 | D30: Hot plate 1 laser read error, please check sensor position!!
A31: 2 | B31: Input Arm | C31: 201000166 | D31: Hot plate 2 laser read error, please check sensor position!!
A32: 2 | B32: Input Arm | C32: 201000170 | D32: Device superfloat at hot plate error!
A33: 2 | B33: Input Arm | C33: 201001300 | D33: In arm X motor error
A34: 2 | B34: Input Arm | C34: 201001301 | D34: In arm Y motor error
A35: 2 | B35: Input Arm | C35: 201001302 | D35: In arm pitch motor error
A36: 2 | B36: Input Arm | C36: 201001303 | D36: In arm Z A motor error
A37: 2 | B37: Input Arm | C37: 201001304 | D37: In arm Z B motor error
... A863: 2 | B863: Motion Log | C863: 222002208 | D863: Do process motor home finish.

Sheet AlarmCodeList_HT9045 PDF
A1: NO | B1: =AlarmCodeList_HT9045!A1 -> Type | C1: Alarm Code | D1: Alarm Message
A2: 1 | B2: =IF(AlarmCodeList_HT9045!A2="","",AlarmCodeList_HT9045!A2) -> 0 | C2: =IF(AlarmCodeList_HT9045!C2="","",AlarmCodeList_HT9045!C2) -> 0 | D2: =IF(AlarmCodeList_HT9045!D2="","",AlarmCodeList_HT9045!D2) -> Unknown alarm code
A3: 2 | B3: =IF(AlarmCodeList_HT9045!A3="","",AlarmCodeList_HT9045!A3) -> 3 | C3: =IF(AlarmCodeList_HT9045!C3="","",AlarmCodeList_HT9045!C3) -> 301000101 | D3: =IF(AlarmCodeList_HT9045!D3="","",AlarmCodeList_HT9045!D3) -> Device pick-up error on the tray
A4: 3 | B4: =IF(AlarmCodeList_HT9045!A4="","",AlarmCodeList_HT9045!A4) -> 1 | C4: =IF(AlarmCodeList_HT9045!C4="","",AlarmCodeList_HT9045!C4) -> 101000109 | D4: =IF(AlarmCodeList_HT9045!D4="","",AlarmCodeList_HT9045!D4) -> Device pick-up error on Hot Plate
A5: 4 | B5: =IF(AlarmCodeList_HT9045!A5="","",AlarmCodeList_HT9045!A5) -> 1 | C5: =IF(AlarmCodeList_HT9045!C5="","",AlarmCodeList_HT9045!C5) -> 101000110 | D5: =IF(AlarmCodeList_HT9045!D5="","",AlarmCodeList_HT9045!D5) -> Device pick-up error on Clean Kit
A6: 5 | B6: =IF(AlarmCodeList_HT9045!A6="","",AlarmCodeList_HT9045!A6) -> 1 | C6: =IF(AlarmCodeList_HT9045!C6="","",AlarmCodeList_HT9045!C6) -> 101000111 | D6: =IF(AlarmCodeList_HT9045!D6="","",AlarmCodeList_HT9045!D6) -> Device pick-up error on Shuttle
A7: 6 | B7: =IF(AlarmCodeList_HT9045!A7="","",AlarmCodeList_HT9045!A7) -> 1 | C7: =IF(AlarmCodeList_HT9045!C7="","",AlarmCodeList_HT9045!C7) -> 101000112 | D7: =IF(AlarmCodeList_HT9045!D7="","",AlarmCodeList_HT9045!D7) -> Device pick up error on input rotate kit!
A8: 7 | B8: =IF(AlarmCodeList_HT9045!A8="","",AlarmCodeList_HT9045!A8) -> 1 | C8: =IF(AlarmCodeList_HT9045!C8="","",AlarmCodeList_HT9045!C8) -> 101000114 | D8: =IF(AlarmCodeList_HT9045!D8="","",AlarmCodeList_HT9045!D8) -> Close site pick-up IC error, take out ic.
A9: 8 | B9: =IF(AlarmCodeList_HT9045!A9="","",AlarmCodeList_HT9045!A9) -> 1 | C9: =IF(AlarmCodeList_HT9045!C9="","",AlarmCodeList_HT9045!C9) -> 101000115 | D9: =IF(AlarmCodeList_HT9045!D9="","",AlarmCodeList_HT9045!D9) -> Clean pad pick-up error on shuttle
A10: 9 | B10: =IF(AlarmCodeList_HT9045!A10="","",AlarmCodeList_HT9045!A10) -> 2 | C10: =IF(AlarmCodeList_HT9045!C10="","",AlarmCodeList_HT9045!C10) -> 201000119 | D10: =IF(AlarmCodeList_HT9045!D10="","",AlarmCodeList_HT9045!D10) -> Loading count is less than ART setting count
A11: 10 | B11: =IF(AlarmCodeList_HT9045!A11="","",AlarmCodeList_HT9045!A11) -> 2 | C11: =IF(AlarmCodeList_HT9045!C11="","",AlarmCodeList_HT9045!C11) -> 201000120 | D11: =IF(AlarmCodeList_HT9045!D11="","",AlarmCodeList_HT9045!D11) -> Loading count is more than ART setting count
A12: 11 | B12: =IF(AlarmCodeList_HT9045!A12="","",AlarmCodeList_HT9045!A12) -> 1 | C12: =IF(AlarmCodeList_HT9045!C12="","",AlarmCodeList_HT9045!C12) -> 101000126 | D12: =IF(AlarmCodeList_HT9045!D12="","",AlarmCodeList_HT9045!D12) -> In arm Device drop error
A13: 12 | B13: =IF(AlarmCodeList_HT9045!A13="","",AlarmCodeList_HT9045!A13) -> 1 | C13: =IF(AlarmCodeList_HT9045!C13="","",AlarmCodeList_HT9045!C13) -> 101000127 | D13: =IF(AlarmCodeList_HT9045!D13="","",AlarmCodeList_HT9045!D13) -> In arm Vacuum sensor OFF error
... A883: 882 | B883: =IF(AlarmCodeList_HT9045!A883="","",AlarmCodeList_HT9045!A883) | C883: =IF(AlarmCodeList_HT9045!C883="","",AlarmCodeList_HT9045!C883) | D883: =IF(AlarmCodeList_HT9045!D883="","",AlarmCodeList_HT9045!D883)

Sheet AlarmCodeList_HT7045
A1: Alarm Class | B1: Mess Type | C1: Alarm Des | D1: ALID | E1: ALTX
A2: 1 | B2: 0 | C2: MTrayZ | D2: 101000000 | E2: [M01] MTrayZ--Motor Power Off Error
A3: 1 | B3: 0 | C3: MTrayZ | D3: 101000001 | E3: [M01] MTrayZ--Motor Out Of Torque Error
A4: 1 | B4: 0 | C4: MTrayZ | D4: 101000002 | E4: [M01] MTrayZ--Motor CW sensor ON Error
A5: 1 | B5: 0 | C5: MTrayZ | D5: 101000003 | E5: [M01] MTrayZ--Motor CCW sensor ON Error
A6: 1 | B6: 0 | C6: MTrayZ | D6: 101000004 | E6: [M01] MTrayZ--Motor Soft CW position Error
A7: 1 | B7: 0 | C7: MTrayZ | D7: 101000005 | E7: [M01] MTrayZ--Motor Soft CCW position Error
A8: 1 | B8: 0 | C8: MTrayZ | D8: 101000006 | E8: [M01] MTrayZ--Motor position Error,Home and restart
A9: 1 | B9: 0 | C9: MTrayZ | D9: 101000007 | E9: [M01] MTrayZ--Motor Undefine Error
A10: 1 | B10: 0 | C10: MInArmX | D10: 101000100 | E10: [M02] MInArmX--Motor Power Off Error
A11: 1 | B11: 0 | C11: MInArmX | D11: 101000101 | E11: [M02] MInArmX--Motor Out Of Torque Error
A12: 1 | B12: 0 | C12: MInArmX | D12: 101000102 | E12: [M02] MInArmX--Motor CW sensor ON Error
A13: 1 | B13: 0 | C13: MInArmX | D13: 101000103 | E13: [M02] MInArmX--Motor CCW sensor ON Error
... A4821: 3 | B4821: 2 | C4821: ShowSECSGEMMessage | D4821: 307000000 | E4821: SECS GEM Message
A4822: 1 | C4822: ShowMyMessage | D4822: 301045500 | E4822: Please put IC in Socket.
A4823: 1 | C4823: ShowMyMessage | D4823: 301045600 | E4823: Not Supply This Mode
A4824: 1 | C4824: ShowMyMessage | D4824: 301045700 | E4824: When change mode must make sure sitemapping are correct with Tester ?
A4825: 1 | C4825: ShowMyMessage | D4825: 301045800 | E4825: Index Z1 test height too high error
A4826: 1 | C4826: ShowMyMessage | D4826: 301045900 | E4826: Over the motor torque setting up value.
A4827: 1 | C4827: ShowMyMessage | D4827: 301046000 | E4827: Index Arm1 Motor Read Torque Error
A4828: 1 | C4828: ShowMyMessage | D4828: 301046100 | E4828: Has Device drop! Please check Socket!
A4829: 1 | C4829: ShowMyMessage | D4829: 301046200 | E4829: Index Z2 test height too high error
A4830: 1 | C4830: ShowMyMessage | D4830: 301046300 | E4830: Index Arm2 Motor Read Torque Error
A4831: 1 | C4831: ShowMyMessage | D4831: 301046400 | E4831: Can't use Auto-3, Because has BIN-
A4832: 1 | C4832: ShowMyMessage | D4832: 301046500 | E4832: Maybe Z1 sucker sensor initial on error
A4833: 1 | C4833: ShowMyMessage | D4833: 301046600 | E4833: Maybe Z2 sucker sensor initial on error
... A5043: 1 | C5043: ShowRecordMessage | D5043: 306010100 | E5043: Download and change recipe finish!

Sheet AlarmCodeList_HT2036
A1: Alarm Class | B1: Mess Type | C1: Alarm Des | D1: ALID | E1: ALTX | G1: No. | H1: Mess Type
A2: 1 | B2: 5 | C2: MStage1TransferY | D2: 10000 | E2: [M01] Motor --Motor Power Off Error | G2: 0 | H2: Sensor
A3: 1 | B3: 5 | C3: MStage1TransferY | D3: 10001 | E3: [M01] Motor --Motor Out Of Torque Error | G3: 4 | H3: Cylinder
A4: 1 | B4: 5 | C4: MStage1TransferY | D4: 10002 | E4: [M01] Motor --Motor CW sensor ON Error | G4: 5 | H4: Motor
A5: 1 | B5: 5 | C5: MStage1TransferY | D5: 10003 | E5: [M01] Motor --Motor CCW sensor ON Error | G5: 6 | H5: Suck
A6: 1 | B6: 5 | C6: MStage1TransferY | D6: 10004 | E6: [M01] Motor --Motor Soft CW position Error | G6: 9 | H6: System
A7: 1 | B7: 5 | C7: MStage1TransferY | D7: 10005 | E7: [M01] Motor --Motor Soft CCW positionError
A8: 1 | B8: 5 | C8: MStage1TransferY | D8: 10006 | E8: [M01] Motor --Motor position Error,Home and restart
A9: 1 | B9: 5 | C9: MStage1TransferY | D9: 10007 | E9: [M01] Motor --Motor Undefine Error
A10: 1 | B10: 5 | C10: MStage2TransferY | D10: 10010 | E10: [M02] Motor --Motor Power Off Error
A11: 1 | B11: 5 | C11: MStage2TransferY | D11: 10011 | E11: [M02] Motor --Motor Out Of Torque Error
A12: 1 | B12: 5 | C12: MStage2TransferY | D12: 10012 | E12: [M02] Motor --Motor CW sensor ON Error
A13: 1 | B13: 5 | C13: MStage2TransferY | D13: 10013 | E13: [M02] Motor --Motor CCW sensor ON Error
A14: 1 | B14: 5 | C14: MStage2TransferY | D14: 10014 | E14: [M02] Motor --Motor Soft CW position Error
A15: 1 | B15: 5 | C15: MStage2TransferY | D15: 10015 | E15: [M02] Motor --Motor Soft CCW positionError
A16: 1 | B16: 5 | C16: MStage2TransferY | D16: 10016 | E16: [M02] Motor --Motor position Error,Home and restart
A17: 1 | B17: 5 | C17: MStage2TransferY | D17: 10017 | E17: [M02] Motor --Motor Undefine Error
A18: 1 | B18: 5 | C18: MStage1TransferZ | D18: 10020 | E18: [M03] Motor --Motor Power Off Error
... A933: 1 | B933: 6 | C933: CCDArm2Suck3 | D933: 68024 | E933: CCDArm2Suck3--Initial Sensor On Error

Sheet AlarmCodeList_HT2000M
A1: Alarm Class | B1: Mess Type | C1: Alarm Des | D1: ALID | E1: ALTX | G1: No. | H1: Mess Type
A2: 1 | B2: 5 | C2: MTransferOneX | D2: 10000 | E2: [M01] Motor --Motor Power Off Error | G2: 0 | H2: Sensor
A3: 1 | B3: 5 | C3: MTransferOneX | D3: 10001 | E3: [M01] Motor --Motor Out Of Torque Error | G3: 4 | H3: Cylinder
A4: 1 | B4: 5 | C4: MTransferOneX | D4: 10002 | E4: [M01] Motor --Motor CW sensor ON Error | G4: 5 | H4: Motor
A5: 1 | B5: 5 | C5: MTransferOneX | D5: 10003 | E5: [M01] Motor --Motor CCW sensor ON Error | G5: 6 | H5: Suck
A6: 1 | B6: 5 | C6: MTransferOneX | D6: 10004 | E6: [M01] Motor --Motor Soft CW position Error | G6: 9 | H6: System
A7: 1 | B7: 5 | C7: MTransferOneX | D7: 10005 | E7: [M01] Motor --Motor Soft CCW positionError
A8: 1 | B8: 5 | C8: MTransferOneX | D8: 10006 | E8: [M01] Motor --Motor position Error,Home and restart
A9: 1 | B9: 5 | C9: MTransferOneX | D9: 10007 | E9: [M01] Motor --Motor Undefine Error
A10: 1 | B10: 5 | C10: MTransferTwoX | D10: 10010 | E10: [M02] Motor --Motor Power Off Error
A11: 1 | B11: 5 | C11: MTransferTwoX | D11: 10011 | E11: [M02] Motor --Motor Out Of Torque Error
A12: 1 | B12: 5 | C12: MTransferTwoX | D12: 10012 | E12: [M02] Motor --Motor CW sensor ON Error
A13: 1 | B13: 5 | C13: MTransferTwoX | D13: 10013 | E13: [M02] Motor --Motor CCW sensor ON Error
A14: 1 | B14: 5 | C14: MTransferTwoX | D14: 10014 | E14: [M02] Motor --Motor Soft CW position Error
A15: 1 | B15: 5 | C15: MTransferTwoX | D15: 10015 | E15: [M02] Motor --Motor Soft CCW positionError
A16: 1 | B16: 5 | C16: MTransferTwoX | D16: 10016 | E16: [M02] Motor --Motor position Error,Home and restart
A17: 1 | B17: 5 | C17: MTransferTwoX | D17: 10017 | E17: [M02] Motor --Motor Undefine Error
A18: 1 | B18: 5 | C18: MTransferOneZ | D18: 10020 | E18: [M03] Motor --Motor Power Off Error
... A1360: 1 | B1360: 6 | C1360: TRArmTwoSuck3 | D1360: 68024 | E1360: TRArmTwoSuck3--Initial Sensor On Error

Sheet SF_List
B2: STREAM 1: Equipment Status
B3: Stream | C3: Function Name | D3: Direction | E3: HT-704X | F3: HT9045 HT9046 | G3: HT-9040 | H3: HT-9080A
B4: S1,F1 | C4: Are You There Request ® | D4: S,H<->E | E4: V | F4: V
B5: S1,F2 | C5: On-Line Data (D) | D5: S,H<->E | E5: V | F5: V
B6: S1,F3 | C6: Selected Equipment Status Request (SSR) | D6: S,H->E | E6: V | F6: V
B7: S1,F4 | C7: Selected Equipment Status Data (SSD) | D7: M,H<-E | E7: V | F7: V
B8: S1,F11 | C8: Status Variable Namelist Request (SVNR) | D8: S,H->E | E8: V | F8: V
B9: S1,F12 | C9: Status Variable Namelist Reply (SVNRR) | D9: M,H<-E | E9: V | F9: V
B10: S1,F13 | C10: Establish Communications Request (CR) | D10: S,H<->E,reply | E10: V | F10: V
B11: S1,F14 | C11: Establish Communications Request Acknowledge (CRA) | D11: S,H<->E | E11: V | F11: V
B12: S1,F15 | C12: Request OFF-LINE (ROFL) | D12: S,H->E,reply | E12: V | F12: V
B13: S1,F16 | C13: OFF-LINE Acknowledge (OFLA) | D13: S,H<-E | E13: V | F13: V
B14: S1,F17 | C14: Request ON-LINE (RONL) | D14: S,H->E,reply | E14: V | F14: V
B15: S1,F18 | C15: ON-LINE Acknowledge (ONLA) | D15: S,H<-E | E15: V | F15: V
B18: STREAM 2: Equipment Control and Diagnostics
B19: Stream | C19: Function Name | D19: Direction | E19: HT-704X | F19: HT9045 HT9046 | G19: HT-9040 | H19: HT-9080A
B20: S2,F13 | C20: Equipment Constant Request (ECR) | D20: S,H->E | E20: V | F20: V
B21: S2,F14 | C21: Equipment Constant Data (ECD) | D21: M,H<-E | E21: V | F21: V
B22: S2,F15 | C22: New Equipment Constant Send (ECS) | D22: S,H->E | E22: V | F22: V
B23: S2,F16 | C23: New Equipment Constant Acknowledge (ECA) | D23: S,H<-E | E23: V | F23: V
B24: S2,F17 | C24: Date and Time Request (DTR) | D24: S,H->E,reply | E24: V | F24: V
B25: S2,F18 | C25: Date and Time Data (DTD) | D25: S,H<->E | E25: V | F25: V
B26: S2,F23 | C26: Trace Initialize Send (TIS) | D26: S,H->E | E26: V | F26: V
B27: S2,F24 | C27: Trace Initialize Acknowledge (TIA) | D27: S,H<-E | E27: V | F27: V
B28: S2,F25 | C28: Loopback Diagnostic Request (LDR) | D28: S,H<->E,reply | E28: V | F28: V
B29: S2,F26 | C29: Loopback Diagnostic Data (LDD) | D29: S,H<->E | E29: V | F29: V
B30: S2,F29 | C30: Equipment Constant Namelist Request (ECNR) | D30: S,H->E | E30: V | F30: V
B31: S2,F30 | C31: Equipment Constant Namelist (ECN) | D31: M,H<-E | E31: V | F31: V
... B39: S2,F38 | C39: Enable/Disable Event Report Acknowledge (EDEA) | D39: S,H<-E | E39: V | F39: V
B40: S2,F39 | C40: Multi-Block Inquire (DMBI) | D40: S,H->E
B41: S2,F40 | C41: Multi-Block Grant (DMBG) | D41: S,H<-E
B42: S2,F41 | C42: Host Command Send (HCS) | D42: S,H->E
B43: S2,F42 | C43: Host Command Acknowledge (HCA) | D43: S,H<-E
B44: S2,F43 | C44: Reset Spooling Streams and Functions (RSSF) | D44: S,H->E
B45: S2,F44 | C45: Reset Spooling Acknowledge (RSA) | D45: M,H<-E
B46: S2,F45 | C46: Define Variable Limit Attributes (DVLA) | D46: M,H->E
B47: S2,F46 | C47: Variable Limit Attribute Acknowledge (VLAA) | D47: M,H<-E
B48: S2,F47 | C48: Variable Limit Attribute Request (VLAR) | D48: S,H->E
B49: S2,F48 | C49: Variable Limit Attributes Send (VLAS) | D49: M,H<-E
B50: S2,F49 | C50: Enhanced Remote Command | D50: M,H->E
...

Sheet SF_List PDF
B2: STREAM 1: Equipment Status
B3: Stream | C3: Function Name | D3: Direction | E3: HT-704X | F3: HT9045 HT9046 | G3: HT-9040 | H3: HT-9080A
B4: S1,F1 | C4: Are You There Request ® | D4: S,H<->E | E4: V | F4: V
B5: S1,F2 | C5: On-Line Data (D) | D5: S,H<->E | E5: V | F5: V
B6: S1,F3 | C6: Selected Equipment Status Request (SSR) | D6: S,H->E | E6: V | F6: V
B7: S1,F4 | C7: Selected Equipment Status Data (SSD) | D7: M,H<-E | E7: V | F7: V
B8: S1,F11 | C8: Status Variable Namelist Request (SVNR) | D8: S,H->E | E8: V | F8: V
B9: S1,F12 | C9: Status Variable Namelist Reply (SVNRR) | D9: M,H<-E | E9: V | F9: V
B10: S1,F13 | C10: Establish Communications Request (CR) | D10: S,H<->E,reply | E10: V | F10: V
B11: S1,F14 | C11: Establish Communications Request Acknowledge (CRA) | D11: S,H<->E | E11: V | F11: V
B12: S1,F15 | C12: Request OFF-LINE (ROFL) | D12: S,H->E,reply | E12: V | F12: V
B13: S1,F16 | C13: OFF-LINE Acknowledge (OFLA) | D13: S,H<-E | E13: V | F13: V
B14: S1,F17 | C14: Request ON-LINE (RONL) | D14: S,H->E,reply | E14: V | F14: V
B15: S1,F18 | C15: ON-LINE Acknowledge (ONLA) | D15: S,H<-E | E15: V | F15: V
B18: STREAM 2: Equipment Control and Diagnostics
B19: Stream | C19: Function Name | D19: Direction | E19: HT-704X | F19: HT9045 HT9046 | G19: HT-9040 | H19: HT-9080A
B20: S2,F13 | C20: Equipment Constant Request (ECR) | D20: S,H->E | E20: V | F20: V
B21: S2,F14 | C21: Equipment Constant Data (ECD) | D21: M,H<-E | E21: V | F21: V
B22: S2,F15 | C22: New Equipment Constant Send (ECS) | D22: S,H->E | E22: V | F22: V
B23: S2,F16 | C23: New Equipment Constant Acknowledge (ECA) | D23: S,H<-E | E23: V | F23: V
B24: S2,F17 | C24: Date and Time Request (DTR) | D24: S,H->E,reply | E24: V | F24: V
B25: S2,F18 | C25: Date and Time Data (DTD) | D25: S,H<->E | E25: V | F25: V
B26: S2,F23 | C26: Trace Initialize Send (TIS) | D26: S,H->E | E26: V | F26: V
B27: S2,F24 | C27: Trace Initialize Acknowledge (TIA) | D27: S,H<-E | E27: V | F27: V
B28: S2,F25 | C28: Loopback Diagnostic Request (LDR) | D28: S,H<->E,reply | E28: V | F28: V
B29: S2,F26 | C29: Loopback Diagnostic Data (LDD) | D29: S,H<->E | E29: V | F29: V
B30: S2,F29 | C30: Equipment Constant Namelist Request (ECNR) | D30: S,H->E | E30: V | F30: V
B31: S2,F30 | C31: Equipment Constant Namelist (ECN) | D31: M,H<-E | E31: V | F31: V
... B39: S2,F38 | C39: Enable/Disable Event Report Acknowledge (EDEA) | D39: S,H<-E | E39: V | F39: V
B40: S2,F39 | C40: Multi-Block Inquire (DMBI) | D40: S,H->E
B41: S2,F40 | C41: Multi-Block Grant (DMBG) | D41: S,H<-E
B42: S2,F41 | C42: Host Command Send (HCS) | D42: S,H->E
B43: S2,F42 | C43: Host Command Acknowledge (HCA) | D43: S,H<-E
B44: S2,F43 | C44: Reset Spooling Streams and Functions (RSSF) | D44: S,H->E
B45: S2,F44 | C45: Reset Spooling Acknowledge (RSA) | D45: M,H<-E
B46: S2,F45 | C46: Define Variable Limit Attributes (DVLA) | D46: M,H->E
B47: S2,F46 | C47: Variable Limit Attribute Acknowledge (VLAA) | D47: M,H<-E
B48: S2,F47 | C48: Variable Limit Attribute Request (VLAR) | D48: S,H->E
B49: S2,F48 | C49: Variable Limit Attributes Send (VLAS) | D49: M,H<-E
B50: S2,F49 | C50: Enhanced Remote Command | D50: M,H->E
...

Sheet S1
B2: Stream,Function Name (Mnemonic) | G2: Direction
B3: S1,F1 Are You There Request ® | G3: S,H->E,reply
B4: Description
B5: Establishes if the equipment is on-line. A function 0 response to this message means the communication is inoperative. In the equipment, a function 0 is equivalent to a timeout on the receive timer after issuing S1,F1 to the host.
B6: Structure
B7: Header only
B9: Exception
B10: None
B12: Stream,Function Name (Mnemonic) | G12: Direction
B13: S1,F2 On Line Data (D) | G13: S,H->E,reply
B14: Description
B15: Data signifying that the equipment is alive.
B16: Structure
B17: L,2 1. <MDLN> 2. <SOFTREV>
B18: MDLN | C18: SOFTREV
B19: Exception
B20: None
B23: Stream,Function Name (Mnemonic) | G23: Direction
B24: S1,F3 Selected Equipment Status Request (SSR) | G24: S,H->E,reply
B25: Description
B26: A request to the equipment to report selected values of its status.
B27: Structure
B28: The following structure is approved for all item formats and should be used by all new implementations: L,n 1. <SVID1> . . n. <SVIDn> The following structure is included for compatibility with previous implementations and may only be used for items of format 3() and 5(): <SVID1,...,SVIDn>
B29: SVID
B30: Exception
B31: A zero-length list (structure 1) or item (structure 2) means report all SVIDs.
B33: Stream,Function Name (Mnemonic) | G33: Direction
B34: S1,F4 Selected Equipment Status Data (SSD) | G34: M,H<-E
B35: Description
B36: The equipment reports the value of each SVID requested in the order requested. The host remembers the names of values requested.
B37: Structure
B38: L,n 1. <SV1> . . n. <SVn>
B39: SV
B40: Exception
B41: None
B44: Stream,Function Name (Mnemonic) | G44: Direction
B45: S1,F11 Status Variable Namelist Request (SVNR) | G45: S,H->E,reply
B46: Description
B47: A request to the equipment to identify certain status variables.
B48: Structure
...

Sheet S2
B2: Stream,Function Name (Mnemonic) | G2: Direction
B3: S2,F13 Equipment Constant Request (ECR) | G3: S,H->E,reply
B4: Description
B5: Constants such as for calibration, servo gain, alarm limits, data collection mode, and other values that are changed infrequently can be obtained using this message. from the primary message.
B6: Structure
B7: The following structure is approved for all item formats and should be used by all new implementations: L,n 1. <ECID1> . . n. <ECIDn> The following structure is included for compatibility with previous implementations and may only be used for items of format 3() and 5(): <ECID1, . . . , ECIDn>
B8: ECID
B9: Exception
B10: A zero-length list (structure1) or item (structure2) means report all ECVs according to a predefined order.
B12: Stream,Function Name (Mnemonic) | G12: Direction
B13: S2,F14 Equipment Constant Data (ECD) | G13: M,H<-E
B14: Description
B15: Data Response to S2,F13 in the order requested.
B16: Structure
B17: L,n 1. <ECV1> 2. <ECV2> . . n. <ECVn>
B18: ECV
B19: Exception
B20: A zero-length list item for ECVi means that ECIDi does not exist. The list format for this data item is not allowed, except in this case.
B23: Stream,Function Name (Mnemonic) | G23: Direction
B24: S2,F15 New Equipment Constant Send (ECS) | G24: S,H->E,reply
B25: Description
B26: Change one or more equipment constants.
B27: Structure
